File: Homework 1/HW1 Question 2/recoilcurves_input/FEPD_CA500C_1HR_1X1MMSQUARE_TRANS_DCD_08_06_24.csv
[Header],B,C,D,E,F,G,H,I,J,K,L,M,N,O,P,Q,R,S,T,U,V,W,X,Y,Z,AA,AB,AC,AD,AE,AF,AG,AH,AI,AJ,AK,AL,AM,AN,AO,AP,AQ,AR,AS,AT,AU,AV,AW,AX
; VSM Data File (default extension .dat),,,,,,,,,,,,,,,,,,,,,,,,,,,,,,,,,,,,,,,,,,,,,,,,,
; Copyright (c) 2003-2008, Quantum Design, Inc. All rights reserved.,,,,,,,,,,,,,,,,,,,,,,,,,,,,,,,,,,,,,,,,,,,,,,,
TITLE,,,,,,,,,,,,,,,,,,,,,,,,,,,,,,,,,,,,,,,,,,,,,,,,,
FILEOPENTIME,3932116685.28272,08/06/2024,2:38 pm,,,,,,,,,,,,,,,,,,,,,,,,,,,,,,,,,,,,,,,,,,,,,,
BYAPP,VSM,2.0,1.0,,,,,,,,,,,,,,,,,,,,,,,,,,,,,,,,,,,,,,,,,,,,,,
INFO,VersaLab VSM Option Release 1.4.6 Build 14,APPNAME,,,,,,,,,,,,,,,,,,,,,,,,,,,,,,,,,,,,,,,,,,,,,,,
INFO,Quantum Design Linear Motor Servo Controller,MOTOR_MODULE_NAME,,,,,,,,,,,,,,,,,,,,,,,,,,,,,,,,,,,,,,,,,,,,,,,
INFO,3101-100 E4,MOTOR_HW_VERSION,,,,,,,,,,,,,,,,,,,,,,,,,,,,,,,,,,,,,,,,,,,,,,,
INFO,MMC552,MOTOR_SERIAL_NUMBER,,,,,,,,,,,,,,,,,,,,,,,,,,,,,,,,,,,,,,,,,,,,,,,
INFO,SRV No X-over 01.03.11,MOTOR_SOFTWARE_VERSION,,,,,,,,,,,,,,,,,,,,,,,,,,,,,,,,,,,,,,,,,,,,,,,
INFO,Quantum Design VSM Detection Module,VSM_MODULE_NAME,,,,,,,,,,,,,,,,,,,,,,,,,,,,,,,,,,,,,,,,,,,,,,,
INFO,3101-150 F0,VSM_HW_VERSION,,,,,,,,,,,,,,,,,,,,,,,,,,,,,,,,,,,,,,,,,,,,,,,
INFO,VSM398,VSM_SERIAL_NUMBER,,,,,,,,,,,,,,,,,,,,,,,,,,,,,,,,,,,,,,,,,,,,,,,
INFO,VSM No X-over 01.02.05 May 20 2008 13:51:47,VSM_SOFTWARE_VERSION,,,,,,,,,,,,,,,,,,,,,,,,,,,,,,,,,,,,,,,,,,,,,,,
INFO,383,PREAMP_SERIAL_NUMBER,,,,,,,,,,,,,,,,,,,,,,,,,,,,,,,,,,,,,,,,,,,,,,,
INFO,Quantum Design VSM Oven,OVEN_MODULE_NAME,,,,,,,,,,,,,,,,,,,,,,,,,,,,,,,,,,,,,,,,,,,,,,,
INFO,3101-200 D0,OVEN_HW_VERSION,,,,,,,,,,,,,,,,,,,,,,,,,,,,,,,,,,,,,,,,,,,,,,,
INFO,OVN234,OVEN_SERIAL_NUMBER,,,,,,,,,,,,,,,,,,,,,,,,,,,,,,,,,,,,,,,,,,,,,,,
INFO,01.01.10,OVEN_SOFTWARE_VERSION,,,,,,,,,,,,,,,,,,,,,,,,,,,,,,,,,,,,,,,,,,,,,,,
INFO,802,COIL_SERIAL_NUMBER,,,,,,,,,,,,,,,,,,,,,,,,,,,,,,,,,,,,,,,,,,,,,,,
INFO,0,MOMENT_UNITS,,,,,,,,,,,,,,,,,,,,,,,,,,,,,,,,,,,,,,,,,,,,,,,
INFO,FePd,SAMPLE_MATERIAL,,,,,,,,,,,,,,,,,,,,,,,,,,,,,,,,,,,,,,,,,,,,,,,
INFO,CA 500C 1hr 1x1mm TRANS ,SAMPLE_COMMENT,,,,,,,,,,,,,,,,,,,,,,,,,,,,,,,,,,,,,,,,,,,,,,,
INFO,0.194,SAMPLE_MASS,,,,,,,,,,,,,,,,,,,,,,,,,,,,,,,,,,,,,,,,,,,,,,,
INFO,,SAMPLE_VOLUME,,,,,,,,,,,,,,,,,,,,,,,,,,,,,,,,,,,,,,,,,,,,,,,
INFO,,SAMPLE_MOLECULAR_WEIGHT,,,,,,,,,,,,,,,,,,,,,,,,,,,,,,,,,,,,,,,,,,,,,,,
INFO,,SAMPLE_SIZE,,,,,,,,,,,,,,,,,,,,,,,,,,,,,,,,,,,,,,,,,,,,,,,
INFO,,SAMPLE_SHAPE,,,,,,,,,,,,,,,,,,,,,,,,,,,,,,,,,,,,,,,,,,,,,,,
DATATYPE,COMMENT,1,,,,,,,,,,,,,,,,,,,,,,,,,,,,,,,,,,,,,,,,,,,,,,,
DATATYPE,TIME,2,,,,,,,,,,,,,,,,,,,,,,,,,,,,,,,,,,,,,,,,,,,,,,,
STARTUPAXIS,X,2,,,,,,,,,,,,,,,,,,,,,,,,,,,,,,,,,,,,,,,,,,,,,,,
STARTUPAXIS,Y1,5,,,,,,,,,,,,,,,,,,,,,,,,,,,,,,,,,,,,,,,,,,,,,,,
[Data],,,,,,,,,,,,,,,,,,,,,,,,,,,,,,,,,,,,,,,,,,,,,,,,,
Comment,Time Stamp (sec),Temperature (K),Magnetic Field (Oe),Moment (emu),M. Std. Err. (emu),Transport Action,Averaging Time (sec),Frequency (Hz),Peak Amplitude (mm),Center Position (mm),Coil Signal' (mV),Coil Signal" (mV),Range (mV),M. Quad. Signal (emu),M. Raw' (emu),M. Raw" (emu),Min. Temperature (K),Max. Temperature (K),Min. Field (Oe),Max. Field (Oe),Mass (grams),Motor Lag (deg),Pressure (Torr),VSM Status (code),Motor Status (code),Measure Status (code),Measure Count,System Temp. (K),Temp. Status (code),Field Status (code),Chamber Status (code),Motor Current (amps),Motor Heatsink Temp. (C),Map 01,Map 02,Map 03,Map 04,Map 05,Map 06,Map 07,Map 08,Map 09,Map 10,Map 11,Map 12,Map 13,Map 14,Map 15,Map 16
,3932116949.516,299.942321777344,0.0345279453322291,0.00453232695864942,7.95005076468858E-7,1,0.999253354069792,40.0298881530762,1.99456996497977,4.72000008448958,0.0512615932093373,0.0089115825429196,2.5,9.96922830344174E-7,0.00453219888224334,4.00723048206941E-6,299.942535400391,299.942535400391,0.0297851022332907,0.0392707884311676,49.0276488687552,17.0637211771051,48.1885032653809,0,0,0,40,299.941802978516,1,4,1,1.89956665039062,37.6344108581543,,,,,,,,,,,,,,,,
,3932116980.157,299.943023681641,-22.9659118652344,0.00344033788004829,2.49061163976992E-6,1,0.999253354069792,40.0298881530762,1.99454327227181,4.72000008448958,0.0388955506956721,0.00678343603852516,0.25,2.6136960310711E-6,0.00344023935359731,4.8986590341342E-6,299.943237304687,299.943237304687,-23.3809108734131,-22.5509128570557,49.5732255751783,17.069542955655,48.1970596313477,0,0,0,40,299.941802978516,1,6,1,1.9097900390625,41.055721282959,,,,,,,,,,,,,,,,
,3932117010.0855,299.942321777344,-6.61257290840149,0.00347901477392253,9.4000470744122E-7,1,0.999253354069792,40.0298881530762,1.99462027737949,4.72000008448958,0.0393344749587514,0.00685885418096139,0.25,2.54600433480183E-6,0.00347891527973184,4.85666631550929E-6,299.942108154297,299.942108154297,-7.09871482849121,-6.12643098831177,49.0596956380437,17.0768268978021,48.2006607055664,0,0,0,40,299.940368652344,1,6,1,1.90139770507813,43.0107536315918,,,,,,,,,,,,,,,,
,3932117043.112,299.942092895508,-15.5362415313721,0.00339222837358009,8.1496722004522E-7,1,0.999253354069792,40.0298881530762,1.99460188061377,4.72000008448958,0.0383532224598751,0.00668589226494198,0.25,2.32297218338879E-6,0.00339213149140926,4.57599878764631E-6,299.943084716797,299.943084716797,-15.9109258651733,-15.1615571975708,49.2949658223321,17.0797941810331,48.2103462219238,0,0,0,40,299.941802978516,1,6,1,1.9000244140625,44.4770278930664,,,,,,,,,,,,,,,,
,3932117067.045,299.942245483398,-39.4733963012695,0.00252250721819866,2.80471575100986E-6,1,0.999253354069792,40.0298881530762,1.99455769125365,4.72000008448958,0.0285191026266413,0.00497315489238826,0.25,1.86362933811193E-6,0.00252243507308838,3.53900362005967E-6,299.941955566406,299.941955566406,-39.9808807373047,-38.9659118652344,49.3801633309283,17.0803615353361,48.2168769836426,0,0,0,40,299.941955566406,1,6,1,1.9012451171875,44.9657897949219,,,,,,,,,,,,,,,,
,3932117097.053,299.942535400391,-39.9049968719482,0.00201622375620457,9.05724078556124E-7,1,0.999253354069792,40.0298881530762,1.99454791377978,4.72000008448958,0.02279427335549,0.00397933302088064,0.25,1.87351692492101E-6,0.00201616581798763,3.21262039763772E-6,299.942535400391,299.942535400391,-40.3555679321289,-39.4544258117676,49.3121616497552,17.0807415970292,48.2182273864746,0,0,0,40,299.940521240234,1,6,1,1.90185546875,45.9433059692383,,,,,,,,,,,,,,,,
,3932117121.061,299.943023681641,-15.9464964866638,0.00233627591975484,9.46937209687277E-7,1,0.999253354069792,40.0298881530762,1.9945942274696,4.72000008448958,0.0264125954020476,0.00461453544213884,0.25,2.47393580348253E-6,0.00233620854775937,4.02559684198962E-6,299.942657470703,299.942657470703,-16.3472671508789,-15.5457258224487,49.3832898450052,17.0826111979492,48.2094459533691,0,0,0,40,299.941528320313,1,6,1,1.90093994140625,46.4320640563965,,,,,,,,,,,,,,,,
,3932117167.0055,299.942596435547,-31.0904092788696,0.00220726461401683,3.23563595491613E-6,1,0.999253354069792,40.0298881530762,1.99459328385171,4.72000008448958,0.0249558386196615,0.00434945033312411,0.25,1.42957985835938E-6,0.00220720159457728,2.89558365478304E-6,299.942657470703,299.942657470703,-33.568546295166,-28.6122722625732,49.5271094925437,17.0854371063492,48.2297134399414,0,0,0,40,299.943939208984,1,6,1,1.90231323242187,47.8983383178711,,,,,,,,,,,,,,,,
,3932117197.056,299.942321777344,-10.3736510276794,0.00152410101885507,4.01902855974348E-6,1,0.999253354069792,40.0298881530762,1.994601169535,4.72000008448958,0.0172308661881375,0.00300923425424857,0.25,1.51395482618532E-6,0.00152405716730697,2.52620770991957E-6,299.942108154297,299.942108154297,-12.9419031143188,-7.80539894104004,49.3918877587168,17.0848337003108,48.2387199401855,0,0,0,40,299.942108154297,1,6,1,1.90139770507813,47.8983383178711,,,,,,,,,,,,,,,,
,3932117229.953,299.943313598633,-96.8310279846191,-0.000288299382708349,1.01024897781529E-5,1,0.999253354069792,40.0298881530762,1.99462837409132,4.72000008448958,-0.00325704757560246,-0.000583004802560189,0.25,-1.50411373245103E-6,-0.000288290270173972,-1.69555575231008E-6,299.942810058594,299.942810058594,-99.6933364868164,-93.9687194824219,49.738149192736,17.0848586167586,48.2580871582031,0,0,0,40,299.941101074219,1,6,1,1.9000244140625,48.3870964050293,,,,,,,,,,,,,,,,
,3932117275.8915,299.942306518555,-0.143328849226236,0.000977540456671603,6.41795992681059E-7,1,0.999253354069792,40.0298881530762,1.99464791347431,4.72000008448958,0.0110511483668816,0.00193459937121713,0.25,1.36619204325065E-6,0.000977512068782478,2.01542830619965E-6,299.941528320313,299.941528320313,-0.197871580719948,-0.0887861177325249,49.6607679693322,17.0871042077656,48.2675437927246,0,0,0,40,299.941101074219,1,4,1,1.903076171875,48.8758583068848,,,,,,,,,,,,,,,,
,3932117305.88,299.943237304687,-109.541854858398,-0.000827235375691404,9.33877848101659E-6,1,0.999253354069792,40.0298881530762,1.99465739845685,4.72000008448958,-0.00935156829906162,-0.00163953876771171,0.25,-1.36774809675968E-6,-0.000827211188612742,-1.91714726067754E-6,299.943389892578,299.943389892578,-112.053192138672,-107.030517578125,49.6130886296591,17.0888528482911,48.2751998901367,0,0,0,40,299.940368652344,1,6,1,1.90475463867187,49.364616394043,,,,,,,,,,,,,,,,
,3932117336.8975,299.942108154297,-27.9340467453003,-0.000206481622841776,4.09964889548847E-6,1,0.999253354069792,40.0298881530762,1.99464700218187,4.72000008448958,-0.00233432256156569,-0.000408420699866084,0.25,-2.69460491853962E-7,-0.000206475640570432,-4.0659632326583E-7,299.942108154297,299.942108154297,-30.4430122375488,-25.4250812530518,49.3903245016783,17.0880329306599,48.2891616821289,0,0,0,40,299.941955566406,1,6,1,1.89910888671875,49.8533744812012,,,,,,,,,,,,,,,,
,3932117377.8805,299.942535400391,-147.657760620117,-0.00235125423046527,5.188166671376E-7,1,0.999253354069792,40.0298881530762,1.99460817959962,4.72000008448958,-0.0265823655126374,-0.00464268572738307,0.25,-2.36018315865694E-6,-0.0023511865493831,-3.92178555330629E-6,299.942535400391,299.942535400391,-147.657760620117,-147.657760620117,49.2722985952744,17.0885889116137,48.2826309204102,0,0,0,40,299.942108154297,1,6,1,1.90048217773438,50.3421325683594,,,,,,,,,,,,,,,,
,3932117409.8605,299.943450927734,-49.9005470275879,-0.000810539384136153,6.19820669883141E-6,1,0.999253354069792,40.0298881530762,1.99468445100336,4.72000008448958,-0.00916244635363597,-0.00160934877246555,0.25,-1.59479748745581E-6,-0.000810515510530077,-2.13310267127402E-6,299.943389892578,299.943389892578,-54.9350814819336,-44.8660125732422,49.6177784007745,17.0892480351429,48.2808303833008,0,0,0,40,299.941955566406,1,6,1,1.89865112304687,50.3421325683594,,,,,,,,,,,,,,,,
,3932117440.8105,299.94352722168,-129.253131866455,-0.00317387775383154,5.23900618411227E-6,1,0.999253354069792,40.0298881530762,1.99467216785412,4.72000008448958,-0.0358860277049822,-0.0062539864369371,0.25,-2.01774804453378E-6,-0.003173787071628,-4.12572907904802E-6,299.943817138672,299.943817138672,-134.244979858398,-124.261283874512,49.4387854698706,17.0897666900167,48.2808303833008,0,0,0,40,299.939086914063,1,6,1,1.90185546875,50.8308906555176,,,,,,,,,,,,,,,,
,3932117473.726,299.942596435547,-82.1566581726074,-0.00213941751717051,6.48626877351336E-6,1,0.999253354069792,40.0298881530762,1.99463926427886,4.72000008448958,-0.0241867543816143,-0.00423040113494526,0.25,-2.67246019982637E-6,-0.0021393555805398,-4.09336120549481E-6,299.942535400391,299.942535400391,-87.195930480957,-77.1173858642578,49.4825566669475,17.0889180532232,48.2950172424316,0,0,0,40,299.943389892578,1,6,1,1.91238403320313,50.8308906555176,,,,,,,,,,,,,,,,
,3932117503.821,299.943817138672,-197.742225646973,-0.00464953187488366,4.24783912364534E-6,1,0.999253354069792,40.0298881530762,1.99465802802755,4.72000008448958,-0.0525713879622444,-0.00915606531787249,0.25,-2.46331479263345E-6,-0.0046493993180233,-5.55136898784646E-6,299.943237304687,299.943237304687,-202.793350219727,-192.691101074219,49.4551996687745,17.0890282001602,48.2965927124023,0,0,0,40,299.939819335937,1,6,1,1.90170288085938,51.3196487426758,,,,,,,,,,,,,,,,
,3932117536.714,299.943954467773,-23.027569770813,-0.00203255360493387,1.08315150895924E-5,1,0.999253354069792,40.0298881530762,1.99465387090569,4.72000008448958,-0.0229794524751197,-0.00401528756380368,0.25,-2.19998800444935E-6,-0.00203249490129867,-3.54992193999342E-6,299.943511962891,299.943511962891,-31.9939250946045,-14.0612144470215,49.7569082771976,17.0873578983159,48.3130340576172,0,0,0,40,299.9423828125,1,6,1,1.905517578125,51.3196487426758,,,,,,,,,,,,,,,,
,3932117567.742,299.9423828125,-141.202743530273,-0.00466328226355198,1.04664912662216E-5,1,0.999253354069792,40.0298881530762,1.99467445094872,4.72000008448958,-0.0527253298924581,-0.00919445630128983,0.25,-3.46455160602554E-6,-0.00466314886035187,-6.56174162500327E-6,299.941955566406,299.941955566406,-151.37141418457,-131.034072875977,49.7459654779283,17.0903412054626,48.3071784973145,0,0,0,40,299.942535400391,1,6,1,1.91146850585938,51.3196487426758,,,,,,,,,,,,,,,,
,3932117601.658,299.942749023438,-286.627944946289,-0.00589837905213291,1.09489633979531E-5,1,0.999253354069792,40.0298881530762,1.99466355434566,4.72000008448958,-0.0666850883174255,-0.0116554782472353,0.25,-6.67081377758209E-6,-0.00589820873355117,-1.05881963453459E-5,299.942108154297,299.942108154297,-295.587188720703,-277.668701171875,49.738149192736,17.0884724900777,48.3033485412598,0,0,0,40,299.943084716797,1,6,1,1.90444946289062,51.808406829834,,,,,,,,,,,,,,,,
,3932117631.617,299.943099975586,-84.2624816894531,-0.0047452536674034,1.4256025026084E-5,1,0.999253354069792,40.0298881530762,1.99478854519242,4.72000008448958,-0.053655290482153,-0.00935544801845789,0.25,-3.42429115543759E-6,-0.00474511787991865,-6.57593017174191E-6,299.943389892578,299.943389892578,-94.2580337524414,-74.2669296264648,49.7303329075437,17.0864589701417,48.296142578125,0,0,0,40,299.942810058594,1,6,1,1.90261840820313,51.808406829834,,,,,,,,,,,,,,,,
,3932117679.6375,299.942962646484,-342.209381103516,-0.00715454959510105,8.5189507504984E-6,1,0.999253354069792,40.0298881530762,1.99475326909165,4.72000008448958,-0.0808925962258386,-0.0141258777435067,0.25,-6.98918773231961E-6,-0.0071543436908827,-1.17408544239891E-5,299.942535400391,299.942535400391,-352.273712158203,-332.145050048828,49.9093258384476,17.0872880502941,48.3206901550293,0,0,0,40,299.940948486328,1,6,1,1.90093994140625,51.808406829834,,,,,,,,,,,,,,,,
,3932117709.625,299.943237304687,-218.42578125,-0.0070181285934049,8.80344274379087E-6,1,0.999253354069792,40.0298881530762,1.99471176787203,4.72000008448958,-0.0793509478231513,-0.0138425445576151,0.25,-5.64373174265314E-6,-0.00701792735628701,-1.03048728256776E-5,299.943939208984,299.943939208984,-228.437927246094,-208.413635253906,49.741275706813,17.089481464658,48.3089790344238,0,0,0,40,299.939086914063,1,6,1,1.90109252929687,52.2971649169922,,,,,,,,,,,,,,,,
,3932117755.6085,299.942886352539,-209.338485717773,-0.00627805363175844,1.0590804072847E-5,1,0.999253354069792,40.0298881530762,1.99473645314317,4.72000008448958,-0.0709813741673502,-0.0123985922027421,0.25,-6.43009269911456E-6,-0.00627787276583831,-1.05996776940941E-5,299.942535400391,299.942535400391,-219.47395324707,-199.203018188477,49.402830557986,17.0889213694533,48.2963676452637,0,0,0,40,299.940521240234,1,6,1,1.91131591796875,52.2971649169922,,,,,,,,,,,,,,,,
,3932117786.521,299.943313598633,-560.110015869141,-0.00977720367420517,4.29366362193029E-6,1,0.999253354069792,40.0298881530762,1.99473709090663,4.72000008448958,-0.110590233055428,-0.0192312941640788,2.5,-2.64104279969215E-6,-0.00977692678663941,-9.13458848938399E-6,299.943389892578,299.943389892578,-568.993347167969,-551.226684570313,49.7780122472168,17.0881419706938,48.3103294372559,0,0,0,40,299.940521240234,1,6,1,1.90139770507813,52.7859268188477,,,,,,,,,,,,,,,,
,3932117810.516,299.943023681641,-82.8941688537598,-0.0057284354164357,1.47918016399606E-5,1,0.999253354069792,40.0298881530762,1.99469938243511,4.72000008448958,-0.0647973231495018,-0.0112442946335906,2.5,4.9144999554385E-7,-0.00572827458029642,-3.31331714336177E-6,299.943389892578,299.943389892578,-92.8019790649414,-72.9863586425781,49.6552965696976,17.0907945102386,48.3083038330078,0,0,0,40,299.940948486328,1,6,1,1.90338134765625,52.7859268188477,,,,,,,,,,,,,,,,
,3932117843.46,299.943099975586,-343.926284790039,-0.00806756497562636,8.22188905689982E-6,1,0.999253354069792,40.0298881530762,1.9947286548702,4.72000008448958,-0.0912500821569076,-0.0158800123356028,2.5,-3.20114158823218E-6,-0.00806733586937994,-8.55931183685364E-6,299.943389892578,299.943389892578,-353.838836669922,-334.013732910156,49.9601316921976,17.0897425118227,48.3188896179199,0,0,0,40,299.941101074219,1,6,1,1.90017700195313,52.7859268188477,,,,,,,,,,,,,,,,
,3932117874.522,299.942596435547,-798.689514160156,-0.0115233462952251,6.46959834310802E-7,1,0.999253354069792,40.0298881530762,1.99473870128647,4.72000008448958,-0.13033779646355,-0.0226843839286946,2.5,-4.74768301406435E-6,-0.0115230191441381,-1.24007232153307E-5,299.942108154297,299.942108154297,-798.689514160156,-798.689514160156,49.6717107686014,17.0894460216103,48.3218154907227,0,0,0,40,299.941101074219,1,6,1,1.9024658203125,53.2746849060059,,,,,,,,,,,,,,,,
,3932117897.489,299.944458007812,-338.820602416992,-0.00917326827120871,6.85478241135087E-6,1,0.999253354069792,40.0298881530762,1.99472722430587,4.72000008448958,-0.103760620409602,-0.0180316832630317,2.5,-1.45123183677981E-6,-0.00917300883242896,-7.54379951542877E-6,299.945526123047,299.945526123047,-348.873077392578,-328.768127441406,50.0992615686207,17.0899933678516,48.3211402893066,0,0,0,40,299.93994140625,1,6,1,1.89956665039062,52.7859268188477,,,,,,,,,,,,,,,,
,3932117931.3995,299.943084716797,-107.528518676758,-0.00586677583044779,1.77939717926667E-5,1,0.999253354069792,40.0298881530762,1.99476566225557,4.72000008448958,-0.0663532834274379,-0.0115795865966139,2.5,-5.09941168345021E-6,-0.00586660737840388,-8.99589793677424E-6,299.943084716797,299.943084716797,-120.00220489502,-95.0548324584961,49.690469853063,17.0882246250017,48.3164100646973,0,0,0,40,299.940948486328,1,6,1,1.90139770507813,53.2746849060059,,,,,,,,,,,,,,,,
,3932117955.406,299.942108154297,-705.767608642578,-0.0110254523693338,5.89647013503378E-6,1,0.999253354069792,40.0298881530762,1.99476146296434,4.72000008448958,-0.124707944025823,-0.021702565394955,2.5,-4.37238539248973E-6,-0.0110251396268968,-1.1694847034401E-5,299.941680908203,299.941680908203,-718.269775390625,-693.265441894531,49.5622827759091,17.0893936849433,48.2981719970703,0,0,0,40,299.938934326172,1,6,1,1.91009521484375,53.2746849060059,,,,,,,,,,,,,,,,
,3932117985.383,299.943450927734,-744.175201416016,-0.0118085665150424,4.68539988253814E-6,1,0.999253354069792,40.0298881530762,1.99476042614259,4.72000008448958,-0.133569455818987,-0.0232218794040062,2.5,-2.72399245884708E-6,-0.0118082323721336,-1.05665348372551E-5,299.943084716797,299.943084716797,-756.786437988281,-731.56396484375,50.0820657411976,17.0876654673539,48.2979469299316,0,0,0,40,299.941802978516,1,6,1,1.904296875,53.7634429931641,,,,,,,,,,,,,,,,
,3932118009.422,299.943161010742,-147.947067260742,-0.00765268982074533,1.51500461386883E-5,1,0.999253354069792,40.0298881530762,1.99475427727556,4.72000008448958,-0.0865619037032591,-0.0150445959300102,2.5,-1.35925186104511E-6,-0.00765247358842489,-6.44200577405119E-6,299.943237304687,299.943237304687,-160.548812866211,-135.345321655273,49.6130886296591,17.0882212695592,48.2932167053223,0,0,0,40,299.937530517578,1,6,1,1.8988037109375,53.2746849060059,,,,,,,,,,,,,,,,
,3932118050.3185,299.943161010742,-451.50830078125,-0.00987787337319563,1.00391531850026E-5,1,0.999253354069792,40.0298881530762,1.99476434679569,4.72000008448958,-0.111725294166303,-0.0194588628076693,2.5,-5.25844029575622E-6,-0.00987759195486833,-1.18188451082228E-5,299.943511962891,299.943511962891,-466.742340087891,-436.274261474609,49.707665680486,17.090478711251,48.2632675170898,0,0,0,40,299.941101074219,1,6,1,1.9024658203125,53.2746849060059,,,,,,,,,,,,,,,,
,3932118074.3015,299.942810058594,-1165.99700927734,-0.0133972917147734,5.45566001445648E-6,1,0.999253354069792,40.0298881530762,1.99489445449304,4.72000008448958,-0.151546901618807,-0.0263640018148957,2.5,-4.51801079508641E-6,-0.0133969119708151,-1.34152652260236E-5,299.943084716797,299.943084716797,-1180.99157714844,-1151.00244140625,49.9085442099284,17.0873937349846,48.2652931213379,0,0,0,40,299.941101074219,1,6,1,1.91070556640625,53.2746849060059,,,,,,,,,,,,,,,,
,3932118105.276,299.943313598633,-1161.24468994141,-0.0137805149395326,4.0607900951091E-6,1,0.999253354069792,40.0298881530762,1.99477600962018,4.72000008448958,-0.155874854068131,-0.0271054174852346,2.5,-3.66036387824842E-6,-0.0137801247733139,-1.28121343287023E-5,299.943817138672,299.943817138672,-1176.2392578125,-1146.25012207031,49.6349742281976,17.0886204359903,48.2565116882324,0,0,0,40,299.941528320313,1,6,1,1.91192626953125,53.7634429931641,,,,,,,,,,,,,,,,
,3932118129.2305,299.943603515625,-452.103515625,-0.0108623398465227,8.75977736008307E-6,1,0.999253354069792,40.0298881530762,1.99480174945492,4.72000008448958,-0.122871109092959,-0.0213488844819487,2.5,-1.38816197878276E-6,-0.0108620331507828,-8.60251221579834E-6,299.943389892578,299.943389892578,-466.988952636719,-437.218078613281,49.6216865433706,17.0887764432738,48.2578620910645,0,0,0,40,299.939819335937,1,6,1,1.90200805664062,53.7634429931641,,,,,,,,,,,,,,,,
,3932118163.259,299.942672729492,-319.144897460937,-0.0092435108013626,2.19970276076857E-5,1,0.999253354069792,40.0298881530762,1.99478260078753,4.72000008448958,-0.104553197845729,-0.0181976023479438,2.5,-3.88085069042264E-6,-0.00924324827960491,-1.0020057359579E-5,299.942535400391,299.942535400391,-347.526123046875,-290.763671875,49.7592531627553,17.0896440552814,48.2542572021484,0,0,0,40,299.943939208984,1,6,1,1.9012451171875,53.7634429931641,,,,,,,,,,,,,,,,
,3932118187.2315,299.942810058594,-1518.70367431641,-0.0145591084618622,5.89588053256433E-6,1,0.999253354069792,40.0298881530762,1.99476796245893,4.72000008448958,-0.164678082675209,-0.0286540366888149,2.5,-5.39559593703647E-6,-0.0145586954996597,-1.50640131468511E-5,299.943084716797,299.943084716797,-1544.13720703125,-1493.27014160156,50.1914937338899,17.0898610861428,48.2630424499512,0,0,0,40,299.943511962891,1,6,1,1.903076171875,53.7634429931641,,,,,,,,,,,,,,,,
,3932118218.229,299.942672729492,-1387.11810302734,-0.0145605082438671,5.38052120896453E-6,1,0.999253354069792,40.0298881530762,1.9947452659149,4.72000008448958,-0.164693745982893,-0.0286470661360881,2.5,-4.56392436830046E-6,-0.0145600958429214,-1.42334499701324E-5,299.942810058594,299.942810058594,-1412.00146484375,-1362.23474121094,49.6435721419091,17.0905719911601,48.2457008361816,0,0,0,40,299.940368652344,1,6,1,1.91513061523438,53.7634429931641,,,,,,,,,,,,,,,,
,3932118242.1915,299.942810058594,-201.719100952148,-0.00877771256250827,2.75949672597251E-5,1,0.999253354069792,40.0298881530762,1.99481753980862,4.72000008448958,-0.0992908948078309,-0.017254045163798,2.5,-1.31284681802158E-6,-0.00877746480295238,-7.14280781196606E-6,299.943084716797,299.943084716797,-226.730499267578,-176.707702636719,49.6935963671399,17.0902633009679,48.2594375610352,0,0,0,40,299.941101074219,1,6,1,1.90292358398438,53.7634429931641,,,,,,,,,,,,,,,,
,3932118275.1655,299.943664550781,-860.846923828125,-0.0127279118816804,9.40270890160927E-6,1,0.999253354069792,40.0298881530762,1.99478136466329,4.72000008448958,-0.1439640452056,-0.0250634291053017,2.5,-5.88692461927677E-6,-0.0127275496897706,-1.43398474987724E-5,299.943389892578,299.943389892578,-883.088439941406,-838.605407714844,49.8350711291207,17.0921267033202,48.2634925842285,0,0,0,40,299.942962646484,1,6,1,1.90032958984375,54.2522010803223,,,,,,,,,,,,,,,,
,3932118299.155,299.943298339844,-2051.97528076172,-0.0156912020475396,3.936379227637E-6,1,0.999253354069792,40.0298881530762,1.99484570000788,4.72000008448958,-0.177486668315498,-0.0309016208672377,2.5,-7.43645818427596E-6,-0.015690755722083,-1.78559277307997E-5,299.943511962891,299.943511962891,-2077.12890625,-2026.82165527344,49.7928631890822,17.0914725433467,48.2650680541992,0,0,0,40,299.942810058594,1,6,1,1.9110107421875,54.2522010803223,,,,,,,,,,,,,,,,
,3932118330.103,299.942947387695,-1842.91998291016,-0.0155042420157789,4.34335046807323E-6,1,0.999253354069792,40.0298881530762,1.99482435401294,4.72000008448958,-0.175376960464753,-0.0304936969198058,2.5,-3.86295316302316E-6,-0.0155038034664994,-1.41586568573326E-5,299.942657470703,299.942657470703,-1867.88391113281,-1817.9560546875,49.6951596241783,17.090876568053,48.2524566650391,0,0,0,40,299.940368652344,1,6,1,1.90200805664062,53.7634429931641,,,,,,,,,,,,,,,,
,3932118354.1015,299.942108154297,-654.201049804687,-0.0122405285678681,1.11323746497492E-5,1,0.999253354069792,40.0298881530762,1.99483650369385,4.72000008448958,-0.138459343305911,-0.0240792916959367,2.5,-3.44779117870895E-6,-0.0122401822894474,-1.15773174983974E-5,299.942108154297,299.942108154297,-679.387939453125,-629.01416015625,49.8077141309476,17.0865119734216,48.2650680541992,0,0,0,40,299.943389892578,1,6,1,1.900634765625,54.2522010803223,,,,,,,,,,,,,,,,
,3932118401.0945,299.943588256836,-407.271759033203,-0.0101827058314672,1.90994747803102E-5,1,0.999253354069792,40.0298881530762,1.99482521046362,4.72000008448958,-0.115172558653037,-0.020082847146729,2.5,-7.44440990495363E-6,-0.0101824142472656,-1.420722877488E-5,299.943939208984,299.943939208984,-432.257080078125,-382.286437988281,49.7756673616591,17.0860976531624,48.2806053161621,0,0,0,40,299.941802978516,1,6,1,1.900634765625,54.2522010803223,,,,,,,,,,,,,,,,
,3932118425.0845,299.942245483398,-1601.08697509766,-0.0149218968566487,5.34712750852343E-6,1,0.999253354069792,40.0298881530762,1.99486737936093,4.72000008448958,-0.168787168339046,-0.0293839488777149,2.5,-6.81122704269179E-6,-0.0149214730229759,-1.67204535686014E-5,299.941955566406,299.941955566406,-1626.46838378906,-1575.70556640625,50.0570536285822,17.0885694777975,48.2927665710449,0,0,0,40,299.943389892578,1,6,1,1.90139770507813,54.2522010803223,,,,,,,,,,,,,,,,
,3932118449.06,299.942596435547,-2792.14172363281,-0.0166523983461431,3.10345828765249E-6,1,0.999253354069792,40.0298881530762,1.99484956271543,4.72000008448958,-0.188364438253634,-0.0327651977495849,2.5,-5.2917272834294E-6,-0.0166519268654489,-1.63484979166841E-5,299.942108154297,299.942108154297,-2813.95874023438,-2770.32470703125,49.9452807503322,17.0894449976774,48.2794799804687,0,0,0,40,299.941528320313,1,6,1,1.90093994140625,54.2522010803223,,,,,,,,,,,,,,,,
,3932118480.03,299.941101074219,-2110.74389648438,-0.0159416339305926,3.79399955994436E-6,1,0.999253354069792,40.0298881530762,1.99481673942886,4.72000008448958,-0.180320432588751,-0.0313737444205407,2.5,-5.73138360507842E-6,-0.015941182784403,-1.63172135684338E-5,299.940521240234,299.940521240234,-2135.337890625,-2086.14990234375,49.7115738230822,17.0884524391016,48.274299621582,0,0,0,40,299.943817138672,1,6,1,1.9122314453125,54.2522010803223,,,,,,,,,,,,,,,,
,3932118503.9695,299.942535400391,-907.943420410156,-0.0133593715613134,7.99325066114774E-6,1,0.999253354069792,40.0298881530762,1.99479700322968,4.72000008448958,-0.151112718643955,-0.0262773896325114,2.5,-3.55425240631476E-6,-0.0133589936145012,-1.2426612646491E-5,299.942535400391,299.942535400391,-933.153991699219,-882.732849121094,50.2805993850822,17.0917002169956,48.296817779541,0,0,0,40,299.943389892578,1,6,1,1.9036865234375,54.7409591674805,,,,,,,,,,,,,,,,
,3932118550.9695,299.943237304687,-241.599334716797,-0.00852368213414119,4.31237460309639E-5,1,0.999253354069792,40.0298881530762,1.99485478118886,4.72000008448958,-0.0964062177218247,-0.0168292599808719,2.5,-7.83882591721577E-6,-0.00852343707410161,-1.34998529136513E-5,299.943084716797,299.943084716797,-274.600067138672,-208.598602294922,49.778793875736,17.0912956281489,48.294116973877,0,0,0,40,299.939514160156,1,6,1,1.91146850585938,54.2522010803223,,,,,,,,,,,,,,,,
,3932118574.9715,299.942810058594,-2042.66967773438,-0.0157281739564834,5.985377537837E-6,1,0.999253354069792,40.0298881530762,1.99490759912649,4.72000008448958,-0.1779150666003,-0.0309472318385903,2.5,-4.96768225584981E-6,-0.0157277284670473,-1.5411804964261E-5,299.943084716797,299.943084716797,-2080.21166992187,-2005.12768554687,49.7451838494091,17.0920936432395,48.2918663024902,0,0,0,40,299.937103271484,1,6,1,1.90261840820313,54.2522010803223,,,,,,,,,,,,,,,,
,3932118598.88,299.942321777344,-3822.55627441406,-0.0174710060337071,2.31853993467991E-6,1,0.999253354069792,40.0298881530762,1.99488466510394,4.72000008448958,-0.197627591524945,-0.034376010138088,2.5,-5.5128397601892E-6,-0.017470511700548,-1.71114980707681E-5,299.942535400391,299.942535400391,-3860.65307617188,-3784.45947265625,50.0726861989668,17.0917105189725,48.2788047790527,0,0,0,40,299.941101074219,1,6,1,1.90353393554687,54.7409591674805,,,,,,,,,,,,,,,,
,3932118628.925,299.9423828125,-2564.25036621094,-0.0165387352610513,4.97947009549588E-6,1,0.999253354069792,40.0298881530762,1.99480930510395,4.72000008448958,-0.187074794377341,-0.0325426741418695,2.5,-5.41010951511653E-6,-0.0165382669750907,-1.63917494025495E-5,299.942108154297,299.942108154297,-2602.40893554687,-2526.091796875,49.7873917894476,17.0909270775932,48.2614631652832,0,0,0,40,299.943389892578,1,6,1,1.9091796875,54.7409591674805,,,,,,,,,,,,,,,,
,3932118652.8635,299.94287109375,-771.498779296875,-0.0128631261402903,1.43279256485572E-5,1,0.999253354069792,40.0298881530762,1.99486128635755,4.72000008448958,-0.145503589188884,-0.0253045516213566,2.5,-3.64078393188209E-6,-0.0128627619426486,-1.21836782956241E-5,299.942657470703,299.942657470703,-809.270812988281,-733.726745605469,49.9718561199861,17.09101788189,48.2459259033203,0,0,0,40,299.941802978516,1,6,1,1.91268920898438,54.7409591674805,,,,,,,,,,,,,,,,
,3932118699.8515,299.942108154297,-821.3603515625,-0.0126986935340656,1.48250149420322E-5,1,0.999253354069792,40.0298881530762,1.99484356607409,4.72000008448958,-0.143639274587787,-0.0249986052781324,2.5,-5.16259559810323E-6,-0.0126983332543643,-1.35962216268965E-5,299.941680908203,299.941680908203,-868.006286621094,-774.714416503906,49.8061508739091,17.0921003503427,48.2409706115723,0,0,0,40,299.9423828125,1,6,1,1.90216064453125,54.2522010803223,,,,,,,,,,,,,,,,
,3932118723.8395,299.942459106445,-2621.54870605469,-0.0164940575698681,4.15905460308894E-6,1,0.999253354069792,40.0298881530762,1.9948354023946,4.72000008448958,-0.186568859259271,-0.0324719992987999,2.5,-6.88311275257369E-6,-0.0164935895297255,-1.78349586060623E-5,299.941528320313,299.941528320313,-2658.39819335938,-2584.69921875,49.8272548439284,17.0913843787589,48.2373695373535,0,0,0,40,299.940521240234,1,6,1,1.900634765625,54.7409591674805,,,,,,,,,,,,,,,,
,3932118747.8455,299.942108154297,-4413.2470703125,-0.0177904317616299,2.81963470588368E-6,1,0.999253354069792,40.0298881530762,1.99480371618297,4.72000008448958,-0.201231876568633,-0.035009584854297,2.5,-6.18383699521208E-6,-0.0177899282213488,-1.79935365786112E-5,299.942535400391,299.942535400391,-4445.63134765625,-4380.86279296875,49.7318961645822,17.0932009830397,48.2430000305176,0,0,0,40,299.944671630859,1,6,1,1.91055297851562,54.7409591674805,,,,,,,,,,,,,,,,
,3932118778.832,299.943023681641,-5928.35961914062,-0.0183678680351055,4.15411002374115E-6,1,0.999253354069792,40.0298881530762,1.9948182304785,4.72000008448958,-0.207768074986956,-0.0361275946099533,2.5,-4.74550802399857E-6,-0.0183673489723399,-1.693571826425E-5,299.943511962891,299.943511962891,-5965.41552734375,-5891.3037109375,49.8850953543514,17.0931354754063,48.2502059936523,0,0,0,40,299.942962646484,1,6,1,1.9012451171875,54.7409591674805,,,,,,,,,,,,,,,,
,3932118802.7405,299.942321777344,-4146.66357421875,-0.0177044954129754,1.53209870046711E-6,1,0.999253354069792,40.0298881530762,1.99487340187046,4.72000008448958,-0.200264974972215,-0.0348507931128435,2.5,-6.96236047081587E-6,-0.0177039936097541,-1.87154394284723E-5,299.942108154297,299.942108154297,-4184.447265625,-4108.8798828125,49.4895913236206,17.0932678979323,48.2547073364258,0,0,0,40,299.940093994141,1,6,1,1.90261840820313,54.7409591674805,,,,,,,,,,,,,,,,
,3932118826.78,299.943389892578,-2341.83215332031,-0.016345075165264,4.79466755821695E-6,1,0.999253354069792,40.0298881530762,1.99482447891064,4.72000008448958,-0.184886545043322,-0.032156364636718,2.5,-4.86151766989458E-6,-0.016344612146659,-1.57148543512653E-5,299.943389892578,299.943389892578,-2379.3291015625,-2304.33520507813,49.7029759093706,17.0932414855455,48.2522315979004,0,0,0,40,299.941802978516,1,6,1,1.900634765625,53.7634429931641,,,,,,,,,,,,,,,,
,3932118850.777,299.942810058594,-547.911422729492,-0.0117893751335442,1.96658696635141E-5,1,0.999253354069792,40.0298881530762,1.99478895386001,4.72000008448958,-0.133354917743017,-0.023180418549279,2.5,-2.36223231208906E-6,-0.0117890419909799,-1.01922131239087E-5,299.942810058594,299.942810058594,-585.7119140625,-510.110931396484,49.7068840519668,17.0922531164652,48.2688941955566,0,0,0,40,299.941101074219,1,6,1,1.90200805664062,54.7409591674805,,,,,,,,,,,,,,,,
,3932118889.6995,299.942672729492,-1292.51489257812,-0.0142758249851667,1.22861665512464E-5,1,0.999253354069792,40.0298881530762,1.99485250048755,4.72000008448958,-0.161477094773703,-0.028116986588025,2.5,-6.99988764761461E-6,-0.0142754189609435,-1.64803903281336E-5,299.943237304687,299.943237304687,-1342.81750488281,-1242.21228027344,50.0351680300438,17.092958170112,48.2637176513672,0,0,0,40,299.941802978516,1,6,1,1.91207885742187,54.7409591674805,,,,,,,,,,,,,,,,
,3932118913.663,299.942520141602,-3683.29211425781,-0.0173904127236572,3.09670268390864E-6,1,0.999253354069792,40.0298881530762,1.99487552699962,4.72000008448958,-0.196712438237135,-0.0342324496778087,2.5,-6.82788427843928E-6,-0.017389919653346,-1.83732207423074E-5,299.943084716797,299.943084716797,-3733.68725585937,-3632.89697265625,50.0976983115822,17.091241373859,48.2652931213379,0,0,0,40,299.941802978516,1,6,1,1.9146728515625,54.7409591674805,,,,,,,,,,,,,,,,
,3932118937.6395,299.9423828125,-6070.66137695313,-0.0184052777360931,3.41635946269599E-6,1,0.999253354069792,40.0298881530762,1.99483910661004,4.72000008448958,-0.208190666469561,-0.0362169215661637,2.5,-6.11507344387602E-6,-0.0184047571034323,-1.83298323182618E-5,299.943084716797,299.943084716797,-6126.6103515625,-6014.71240234375,49.5669725470245,17.0932681128762,48.2583122253418,0,0,0,40,299.941101074219,1,6,1,1.90155029296875,54.7409591674805,,,,,,,,,,,,,,,,
,3932118968.6215,299.943878173828,-7719.93408203125,-0.0187935265967965,1.06939194894557E-6,1,0.999253354069792,40.0298881530762,1.99479697219954,4.72000008448958,-0.212578804275459,-0.0369755142814782,2.5,-5.83819501190305E-6,-0.0187929946804511,-1.83072445470418E-5,299.943084716797,299.943084716797,-7771.154296875,-7668.7138671875,49.8319446150437,17.092431262962,48.2612380981445,0,0,0,40,299.939514160156,1,6,1,1.90353393554687,54.7409591674805,,,,,,,,,,,,,,,,
,3932118992.6585,299.942459106445,-5325.19750976562,-0.0182057677233519,3.75402801883968E-6,1,0.999253354069792,40.0298881530762,1.99485524049037,4.72000008448958,-0.205937232740429,-0.035814735796819,2.5,-5.17406687588987E-6,-0.018205253145494,-1.72578365814089E-5,299.942108154297,299.942108154297,-5362.84619140625,-5287.548828125,49.4489466406206,17.0920724704811,48.2691192626953,0,0,0,40,299.944671630859,1,6,1,1.90139770507813,54.2522010803223,,,,,,,,,,,,,,,,
,3932119016.564,299.941604614258,-2935.87377929687,-0.0169400837171232,4.16926317540572E-6,1,0.999253354069792,40.0298881530762,1.99485657823018,4.72000008448958,-0.191618661249328,-0.0333348128750747,2.5,-5.68852441545297E-6,-0.0169396044283432,-1.69361284427287E-5,299.941528320313,299.941528320313,-2986.693359375,-2885.05419921875,49.473958753236,17.0925818535428,48.2844352722168,0,0,0,40,299.944396972656,1,6,1,1.90277099609375,54.7409591674805,,,,,,,,,,,,,,,,
,3932119040.6375,299.943023681641,-537.363311767578,-0.0117318240218166,2.65807877091941E-5,1,0.999253354069792,40.0298881530762,1.99485368121663,4.72000008448958,-0.132708832886485,-0.0230636232411734,2.5,-1.9654440586904E-6,-0.011731492683087,-9.75721412543315E-6,299.943237304687,299.943237304687,-581.391174316406,-493.33544921875,49.6068356015053,17.0919501211311,48.2727241516113,0,0,0,40,299.941101074219,1,6,1,1.9000244140625,54.7409591674805,,,,,,,,,,,,,,,,
,3932119086.597,299.942810058594,-2246.10229492187,-0.0160636413678257,1.05129936891477E-5,1,0.999253354069792,40.0298881530762,1.99480197988225,4.72000008448958,-0.181695587026291,-0.0316343861616721,2.5,-7.61014531135411E-6,-0.01606318471725,-1.82766834744779E-5,299.943084716797,299.943084716797,-2321.73168945313,-2170.47290039062,49.7193901082745,17.0933649814136,48.2853355407715,0,0,0,40,299.942535400391,1,6,1,1.90048217773438,54.7409591674805,,,,,,,,,,,,,,,,
,3932119110.5415,299.942321777344,-5809.22875976563,-0.0183369690534046,4.6637568988587E-6,1,0.999253354069792,40.0298881530762,1.99486199900096,4.72000008448958,-0.207419990322366,-0.0360846136822861,2.5,-6.24283257384366E-6,-0.0183364502427928,-1.84127539509515E-5,299.942535400391,299.942535400391,-5884.83447265625,-5733.623046875,50.0179722026207,17.0918999460504,48.2740745544434,0,0,0,40,299.940795898438,1,6,1,1.90216064453125,55.2297172546387,,,,,,,,,,,,,,,,
,3932119134.548,299.942962646484,-9402.6044921875,-0.0190699896867217,4.37228557706882E-6,1,0.999253354069792,40.0298881530762,1.99487833252826,4.72000008448958,-0.215713515488129,-0.0375262186340627,2.5,-6.3960524460737E-6,-0.0190694504965644,-1.90449852084062E-5,299.943389892578,299.943389892578,-9477.9638671875,-9327.2451171875,49.8897851254668,17.0899306455205,48.2869110107422,0,0,0,40,299.941375732422,1,6,1,1.90185546875,54.7409591674805,,,,,,,,,,,,,,,,
,3932119165.472,299.942733764648,-7292.45947265625,-0.0187211360027809,5.53214177944598E-6,1,0.999253354069792,40.0298881530762,1.99488314411044,4.72000008448958,-0.211774288090796,-0.0368029437128657,2.5,-3.0144757754756E-6,-0.0187206085786802,-1.54365005958217E-5,299.942657470703,299.942657470703,-7357.8779296875,-7227.041015625,49.6404456278322,17.0911257492681,48.2603378295898,0,0,0,40,299.941528320313,1,6,1,1.90093994140625,54.7409591674805,,,,,,,,,,,,,,,,
,3932119189.502,299.942535400391,-3710.19836425781,-0.017492458435074,6.17227106456353E-6,1,0.999253354069792,40.0298881530762,1.9948876185119,4.72000008448958,-0.197869729640683,-0.0344229143553257,2.5,-5.93009755328641E-6,-0.0174919630898626,-1.75431624477061E-5,299.942535400391,299.942535400391,-3765.97192382812,-3654.4248046875,49.6396639993129,17.0917417493355,48.274974822998,0,0,0,40,299.940368652344,1,6,1,1.90093994140625,54.7409591674805,,,,,,,,,,,,,,,,
,3932119213.411,299.942169189453,-133.047416687012,-0.00768742053096155,0.000115539576483607,1,0.999253354069792,40.0298881530762,1.99485540133504,4.72000008448958,-0.08698229439301,-0.0149794433565491,2.5,1.04951194817466E-5,-0.00768721143045764,5.38893895729908E-6,299.941528320313,299.941528320313,-217.216369628906,-48.8784637451172,50.0633066567361,17.0946036192705,48.2803802490234,0,0,0,40,299.941955566406,1,6,1,1.90414428710938,54.7409591674805,,,,,,,,,,,,,,,,
,3932119259.4705,299.943389892578,-4000.17834472656,-0.0175858420940656,7.57710283136769E-6,1,0.999253354069792,40.0298881530762,1.99491538192012,4.72000008448958,-0.19893037226738,-0.0345976268936394,2.5,-5.12096479022032E-6,-0.0175853442413544,-1.67955245402751E-5,299.943389892578,299.943389892578,-4100.7978515625,-3899.55883789063,49.8155304161399,17.0920983416014,48.2794799804687,0,0,0,40,299.938812255859,1,6,1,1.89987182617187,55.2297172546387,,,,,,,,,,,,,,,,
,3932119283.4275,299.942108154297,-8778.17041015625,-0.0189763981170618,1.97424744296818E-6,1,0.999253354069792,40.0298881530762,1.994839229649,4.72000008448958,-0.214649199053557,-0.0373505149781999,2.5,-7.17402919033069E-6,-0.0189758614173102,-1.97622405468254E-5,299.942108154297,299.942108154297,-8879.017578125,-8677.3232421875,49.8139671591014,17.0932097115621,48.2821807861328,0,0,0,40,299.941955566406,1,6,1,1.89956665039062,55.2297172546387,,,,,,,,,,,,,,,,
,3932119313.411,299.941818237305,-11035.2944335938,-0.0192756122999685,3.94844317858677E-6,1,0.999253354069792,40.0298881530762,1.99482170549221,4.72000008448958,-0.21803361909501,-0.0379291474993404,2.5,-6.4099129051915E-6,-0.0192750683440236,-1.91916608359521E-5,299.941680908203,299.941680908203,-11136.912109375,-10933.6767578125,49.964821463313,17.0957663696692,48.2871360778809,0,0,0,40,299.941802978516,1,6,1,1.90109252929687,54.7409591674805,,,,,,,,,,,,,,,,
,3932119337.4315,299.942947387695,-6226.59204101562,-0.0184873090370609,7.12798679083885E-6,1,0.999253354069792,40.0298881530762,1.99489486879393,4.72000008448958,-0.209123921403555,-0.0363808378589842,2.5,-6.27711019401315E-6,-0.0184867856986314,-1.85459770816903E-5,299.942810058594,299.942810058594,-6326.56884765625,-6126.615234375,50.117239024563,17.0927917354815,48.2774543762207,0,0,0,40,299.941528320313,1,6,1,1.90231323242187,55.2297172546387,,,,,,,,,,,,,,,,
,3932119361.394,299.94189453125,-1461.27728271484,-0.0149485006644388,2.00136583755889E-5,1,0.999253354069792,40.0298881530762,1.99482547969084,4.72000008448958,-0.169091559559679,-0.0293960955182057,2.5,-3.3184181243576E-6,-0.0149480785501629,-1.32455893965274E-5,299.942108154297,299.942108154297,-1561.41540527344,-1361.13916015625,49.799116217236,17.092962191374,48.2713737487793,0,0,0,40,299.943084716797,1,6,1,1.90277099609375,55.2297172546387,,,,,,,,,,,,,,,,
,3932119407.35,299.942535400391,-2565.16577148438,-0.016449115697787,1.00627234226753E-5,1,0.999253354069792,40.0298881530762,1.99491170404803,4.72000008448958,-0.186067847506281,-0.0323819109494523,2.5,-6.61646791996545E-6,-0.0164486490512814,-1.75385581422086E-5,299.942535400391,299.942535400391,-2655.642578125,-2474.68896484375,49.9312114369861,17.0916150135103,48.2673187255859,0,0,0,40,299.940368652344,1,6,1,1.91421508789062,54.7409591674805,,,,,,,,,,,,,,,,
,3932119431.334,299.942321777344,-7326.57202148438,-0.0187203616303813,6.3886236814111E-6,1,0.999253354069792,40.0298881530762,1.99489156276493,4.72000008448958,-0.211762456192499,-0.0368242382753925,2.5,-5.01811625968606E-6,-0.0187198331435484,-1.74395224494584E-5,299.942108154297,299.942108154297,-7427.4736328125,-7225.67041015625,49.9233951517937,17.0931003347379,48.2776794433594,0,0,0,40,299.942108154297,1,6,1,1.9036865234375,54.7409591674805,,,,,,,,,,,,,,,,
,3932119455.2375,299.943084716797,-12110.6279296875,-0.0193875640160338,2.23457169003454E-6,1,0.999253354069792,40.0298881530762,1.99489223168352,4.72000008448958,-0.219304684292453,-0.0381664084142508,2.5,-7.83513603216352E-6,-0.019387015443409,-2.06885498690034E-5,299.942657470703,299.942657470703,-12199.4755859375,-12021.7802734375,49.8741525550822,17.0941762133038,48.2808303833008,0,0,0,40,299.939819335937,1,6,1,1.9110107421875,55.2297172546387,,,,,,,,,,,,,,,,
,3932119486.293,299.942031860352,-11566.6694335938,-0.0193383121341918,2.97045835402277E-6,1,0.999253354069792,40.0298881530762,1.99491182905329,4.72000008448958,-0.218752622694941,-0.0380526368029871,2.5,-6.29567013012048E-6,-0.0193377664799505,-1.91177776230412E-5,299.942535400391,299.942535400391,-11680.333984375,-11453.0048828125,49.7873917894476,17.0926168723716,48.2664184570313,0,0,0,40,299.941802978516,1,6,1,1.9110107421875,55.2297172546387,,,,,,,,,,,,,,,,
,3932119510.2405,299.940734863281,-6805.13916015625,-0.0186235840853648,3.06023015553605E-6,1,0.999253354069792,40.0298881530762,1.99488021475331,4.72000008448958,-0.210662910209559,-0.0366547843500691,2.5,-6.85743922762049E-6,-0.0186230579135627,-1.92156995766646E-5,299.940521240234,299.940521240234,-6905.177734375,-6705.1005859375,49.8600832417361,17.0927742933112,48.2619132995605,0,0,0,40,299.941101074219,1,6,1,1.90048217773438,54.7409591674805,,,,,,,,,,,,,,,,
,3932119534.1795,299.942031860352,-2021.45971679687,-0.0159159599102548,1.51372279919629E-5,1,0.999253354069792,40.0298881530762,1.99490220946451,4.72000008448958,-0.180039422526202,-0.0313131335935312,2.5,-4.71657889418627E-6,-0.0159155096889342,-1.52854687087479E-5,299.941955566406,299.941955566406,-2134.94409179687,-1907.97534179687,49.7014126523322,17.0920212437492,48.2574119567871,0,0,0,40,299.940368652344,1,6,1,1.90032958984375,55.2297172546387,,,,,,,,,,,,,,,,
,3932119568.241,299.940948486328,-2146.96740722656,-0.0159129297000195,1.43357725845903E-5,1,0.999253354069792,40.0298881530762,1.99486061872837,4.72000008448958,-0.179995506811773,-0.0313412833948314,2.5,-7.7867090877718E-6,-0.0159124780740639,-1.83533781412959E-5,299.940795898438,299.940795898438,-2233.49584960938,-2060.43896484375,49.9015095532553,17.0912351206326,48.2702484130859,0,0,0,40,299.93994140625,1,6,1,1.90093994140625,55.2297172546387,,,,,,,,,,,,,,,,
,3932119592.1515,299.943313598633,-6909.72778320312,-0.018624407569054,7.00104447634381E-6,1,0.999253354069792,40.0298881530762,1.99490772538538,4.72000008448958,-0.210672491893807,-0.0366713682890238,2.5,-8.13801901920567E-6,-0.018623879056352,-2.04964546106574E-5,299.942535400391,299.942535400391,-7022.5576171875,-6796.89794921875,49.7983345887168,17.0929325130579,48.269344329834,0,0,0,40,299.939086914063,1,6,1,1.89910888671875,54.7409591674805,,,,,,,,,,,,,,,,
,3932119616.1365,299.941604614258,-11670.4423828125,-0.0193452104053256,6.31440812033585E-6,1,0.999253354069792,40.0298881530762,1.99492174188886,4.72000008448958,-0.218824125941105,-0.0381100481629057,2.5,-1.01570901802379E-5,-0.019344662275034,-2.29834477414192E-5,299.941528320313,299.941528320313,-11770.580078125,-11570.3046875,49.5075687795629,17.0925758919483,48.2767791748047,0,0,0,40,299.9423828125,1,6,1,1.90093994140625,55.2297172546387,,,,,,,,,,,,,,,,
,3932119647.408,299.943450927734,-15943.2568359375,-0.0196904688959561,1.9551237884161E-6,1,0.999253354069792,40.0298881530762,1.99488839467125,4.72000008448958,-0.222727323397944,-0.0387816391818028,2.5,-9.64658661963682E-6,-0.0196899112483569,-2.26914880255943E-5,299.943511962891,299.943511962891,-15985.07421875,-15901.439453125,49.9601316921976,17.0923384703639,48.2925415039063,0,0,0,40,299.941802978516,1,6,1,1.91070556640625,55.2297172546387,,,,,,,,,,,,,,,,
,3932119671.067,299.940948486328,-11239.5234375,-0.0193008340427275,6.18250241115473E-6,1,0.999253354069792,40.0298881530762,1.99490244450589,4.72000008448958,-0.218329741739632,-0.037966917627679,2.5,-5.23944683636431E-6,-0.0193002907182904,-1.80375340648095E-5,299.940368652344,299.940368652344,-11340.3232421875,-11138.7236328125,49.7498736205245,17.0909714286437,48.2830810546875,0,0,0,40,299.944091796875,1,6,1,1.90139770507813,55.2297172546387,,,,,,,,,,,,,,,,
,3932119695.133,299.942092895508,-6435.58349609375,-0.0185380795063582,6.25264681064E-6,1,0.999253354069792,40.0298881530762,1.99488826144207,4.72000008448958,-0.209697269058888,-0.0364823189142136,2.5,-6.44376069171318E-6,-0.0185375551588134,-1.87459516643623E-5,299.943084716797,299.943084716797,-6523.4921875,-6347.6748046875,49.8944748965822,17.094166504826,48.3067283630371,0,0,0,40,299.93994140625,1,6,1,1.91116333007813,54.7409591674805,,,,,,,,,,,,,,,,
,3932119719.037,299.941390991211,-1708.54333496094,-0.0153502122083717,1.69970183315484E-5,1,0.999253354069792,40.0298881530762,1.99492656185573,4.72000008448958,-0.173644540749229,-0.0301846281950221,2.5,-3.15127954481868E-6,-0.0153497791874856,-1.33449491470144E-5,299.941101074219,299.941101074219,-1809.30993652344,-1607.77673339844,49.5575930047937,17.0926533207783,48.3146095275879,0,0,0,40,299.943511962891,1,6,1,1.9091796875,55.2297172546387,,,,,,,,,,,,,,,,
,3932119752.0955,299.94123840332,-3550.07739257812,-0.0173009789513949,1.27235019752003E-5,1,0.999253354069792,40.0298881530762,1.99492902278662,4.72000008448958,-0.195707001365922,-0.0340507345301955,2.5,-6.21364095284157E-6,-0.0173004894681906,-1.7699894896727E-5,299.940795898438,299.940795898438,-3698.70874023438,-3401.44604492188,49.9374644651399,17.0929647120684,48.3305969238281,0,0,0,40,299.941802978516,1,6,1,1.9024658203125,55.2297172546387,,,,,,,,,,,,,,,,
,3932119776.008,299.942108154297,-10614.5825195312,-0.019231248414919,8.02437001250873E-6,1,0.999253354069792,40.0298881530762,1.99487391523535,4.72000008448958,-0.217534705774888,-0.0378576396393315,2.5,-7.70564107068508E-6,-0.019230704583811,-2.04588642044078E-5,299.942535400391,299.942535400391,-10763.009765625,-10466.1552734375,49.7756673616591,17.0924305273727,48.3353271484375,0,0,0,40,299.943389892578,1,6,1,1.90292358398438,55.2297172546387,,,,,,,,,,,,,,,,
,3932119799.995,299.942962646484,-17716.931640625,-0.0198060594882837,6.28911454433806E-6,1,0.999253354069792,40.0298881530762,1.99491214422013,4.72000008448958,-0.224043352216814,-0.0389754323758603,2.5,-6.67399556244103E-6,-0.0198055012771926,-1.97911164409166E-5,299.943389892578,299.943389892578,-17866.53515625,-17567.328125,50.1703897638707,17.0913299395317,48.3465881347656,0,0,0,40,299.940795898438,1,6,1,1.91116333007813,55.2297172546387,,,,,,,,,,,,,,,,
,3932119831.04,299.942031860352,-11773.236328125,-0.0193637084156237,2.23813472280861E-6,1,0.999253354069792,40.0298881530762,1.99485933587285,4.72000008448958,-0.219035588973399,-0.0380945284550127,2.5,-5.67533946468587E-6,-0.0193631625044246,-1.85138294420119E-5,299.941955566406,299.941955566406,-11922.962890625,-11623.509765625,49.7444022208899,17.0931073534864,48.3391571044922,0,0,0,40,299.941802978516,1,6,1,1.90216064453125,55.2297172546387,,,,,,,,,,,,,,,,
,3932119854.949,299.94123840332,-4707.28247070313,-0.0179797688551796,7.90948013751349E-6,1,0.999253354069792,40.0298881530762,1.99491673513945,4.72000008448958,-0.20338119930922,-0.0354037788002309,2.5,-7.98877853374073E-6,-0.017979259332704,-1.99236369245891E-5,299.941528320313,299.941528320313,-4855.87841796875,-4558.6865234375,49.7928631890822,17.0945544056063,48.3420829772949,0,0,0,40,299.943511962891,1,6,1,1.90078735351562,55.2297172546387,,,,,,,,,,,,,,,,
,3932119901.9515,299.942306518555,-1372.98443603516,-0.0145029881699156,3.38701140207369E-5,1,0.999253354069792,40.0298881530762,1.99493156670016,4.72000008448958,-0.164048582220058,-0.0285900750041084,2.5,-9.28486982636561E-6,-0.0145025744139432,-1.89160935906901E-5,299.943511962891,299.943511962891,-1540.50891113281,-1205.4599609375,49.7170452227168,17.0925965830457,48.3508644104004,0,0,0,40,299.938934326172,1,6,1,1.90277099609375,55.2297172546387,,,,,,,,,,,,,,,,
,3932119925.9595,299.941390991211,-8472.7998046875,-0.0189290477126433,8.20926018648416E-6,1,0.999253354069792,40.0298881530762,1.99487997191342,4.72000008448958,-0.214120558861049,-0.0372422476542236,2.5,-5.75850493426127E-6,-0.0189285136411352,-1.83160263556606E-5,299.941680908203,299.941680908203,-8622.0830078125,-8323.5166015625,49.890566753986,17.0938582293192,48.3360023498535,0,0,0,40,299.938385009766,1,6,1,1.89956665039062,55.2297172546387,,,,,,,,,,,,,,,,
,3932119949.859,299.942031860352,-15527.5380859375,-0.0196704086734853,7.32053711074434E-6,1,0.999253354069792,40.0298881530762,1.99487628726983,4.72000008448958,-0.222498111304307,-0.0387477269398957,2.5,-1.01503646194871E-5,-0.0196698520249551,-2.31830626782467E-5,299.942108154297,299.942108154297,-15677.7490234375,-15377.3271484375,49.7701959620245,17.0929433088237,48.3342018127441,0,0,0,40,299.941101074219,1,6,1,1.90963745117187,55.2297172546387,,,,,,,,,,,,,,,,
,3932119980.9205,299.941879272461,-17917.8095703125,-0.0198207997729377,1.09145729455122E-5,1,0.999253354069792,40.0298881530762,1.99489196737737,4.72000008448958,-0.224211856034981,-0.0389813721836187,2.5,-4.67379017734762E-6,-0.019820243185465,-1.78002736954813E-5,299.942657470703,299.942657470703,-18086.759765625,-17748.859375,49.8866586113899,17.090272324723,48.3432083129883,0,0,0,40,299.941101074219,1,6,1,1.90277099609375,54.7409591674805,,,,,,,,,,,,,,,,
,3932120004.855,299.941741943359,-10826.2934570312,-0.0192589761529275,2.47271982273885E-6,1,0.999253354069792,40.0298881530762,1.99493748435363,4.72000008448958,-0.217858861309046,-0.0378913505890004,2.5,-5.76928933907742E-6,-0.0192584330905153,-1.8540498259236E-5,299.941528320313,299.941528320313,-10976.048828125,-10676.5380859375,49.6248130574476,17.0898524883876,48.3549194335937,0,0,0,40,299.941101074219,1,6,1,1.900634765625,55.2297172546387,,,,,,,,,,,,,,,,
,3932120028.863,299.942031860352,-3708.10192871094,-0.0175040186590961,1.00525393720776E-5,1,0.999253354069792,40.0298881530762,1.99491812067778,4.72000008448958,-0.19800448108505,-0.0344400222608823,2.5,-5.39045573075287E-6,-0.0175035236199548,-1.70112374646251E-5,299.942108154297,299.942108154297,-3856.69287109375,-3559.51098632812,49.9984314896399,17.0891387304958,48.3637008666992,0,0,0,40,299.938079833984,1,6,1,1.90277099609375,55.2297172546387,,,,,,,,,,,,,,,,
,3932120042.8115,299.941665649414,-0.392328325659037,-0.00466681432357918,1.38877600977567E-6,1,0.999253354069792,40.0298881530762,1.9949058759726,4.72000008448958,-0.0527905619184918,-0.00918137443841829,2.5,-1.36869928843045E-6,-0.00466668231428797,-4.46833004137563E-6,299.940795898438,299.940795898438,-0.752784729003906,-0.031871922314167,49.5880765170437,17.0903483063302,48.37158203125,0,0,0,40,299.941955566406,1,4,1,1.90292358398438,55.7184753417969,,,,,,,,,,,,,,,,